{"name": "test_get_pro_intent", "status": "broken", "statusDetails": {"message": "UnicodeDecodeError: 'utf-8' codec can't decode byte 0xc3 in position 0: invalid continuation byte", "trace": "self = <test_get_intent.TestIntent object at 0x000001C212F88358>\n\n    @pytest.mark.api_intention_test\n    @allure.feature(\"测试环境通用意图识别\")\n    def test_get_pro_intent(self):\n        # 意图测试\n        GetRequests().get_request(\"http://192.168.1.79:8900/intention/v2/tcnn\", \"GET\", \"intent\",\n                                  \"intent\\\\dermatology\\\\target.txt\",\n                                  \"intent\\\\dermatology\\\\dermatology_test_data_3995.csv\", [\"sentence\"], \"label\",\n                                  \"dermatology_intention_test_result.xls\",\n>                                 \"dermatology_intention_target_test_result.xls\")\n\napi\\test_get_intent.py:23: \n_ _ _ _ _ _ _ _ _ _ _ _ _ _ _ _ _ _ _ _ _ _ _ _ _ _ _ _ _ _ _ _ _ _ _ _ _ _ _ _\n..\\api\\get_requests.py:195: in get_request\n    GetRequests.get_target_result(self, target_file, exp_list, re_list, target_result_file)\n..\\api\\get_requests.py:204: in get_target_result\n    target_list = CommonFunction.get_target(self, target_file)\n..\\common\\common_function.py:305: in get_target\n    for line in file.readlines():\n_ _ _ _ _ _ _ _ _ _ _ _ _ _ _ _ _ _ _ _ _ _ _ _ _ _ _ _ _ _ _ _ _ _ _ _ _ _ _ _\n\nself = <encodings.utf_8.IncrementalDecoder object at 0x000001C21304FA58>\ninput = b'\\xc3\\xe8\\xca\\xf6\\xd6\\xa2\\xd7\\xb4\\r\\n\\xce\\xde\\r\\n\\xc3\\xe8\\xca\\xf6\\xbe\\xcd\\xd5\\xef\\xca\\xb7\\r\\n\\xc8\\xb7\\xb6\\xa8\\xc1\\xaa...bc\\xec\\xb2\\xe9\\xca\\xb1\\xb3\\xa4\\r\\n\\xd7\\xc9\\xd1\\xaf\\xc1\\xf4\\xb0\\xcc\\r\\n\\xd7\\xc9\\xd1\\xaf\\xd3\\xc5\\xbb\\xdd\\xbb\\xee\\xb6\\xaf'\nfinal = False\n\n    def decode(self, input, final=False):\n        # decode input (taking the buffer into account)\n        data = self.buffer + input\n>       (result, consumed) = self._buffer_decode(data, self.errors, final)\nE       UnicodeDecodeError: 'utf-8' codec can't decode byte 0xc3 in position 0: invalid continuation byte\n\nE:\\Python3.7.3\\lib\\codecs.py:322: UnicodeDecodeError"}, "start": 1591586005946, "stop": 1591586106966, "uuid": "2d04ebb6-0066-4e87-808f-0b3f612d9618", "historyId": "5577602bedd8563b8ebaf88513cfdf02", "testCaseId": "49fe48d551064aad013d744258a73f22", "fullName": "pytest.api.test_get_intent.TestIntent#test_get_pro_intent", "labels": [{"name": "feature", "value": "测试环境通用意图识别"}, {"name": "tag", "value": "api_intention_test"}, {"name": "parentSuite", "value": "pytest.api"}, {"name": "suite", "value": "test_get_intent"}, {"name": "subSuite", "value": "TestIntent"}, {"name": "host", "value": "WIN-OQ20V7UABJF"}, {"name": "thread", "value": "10288-MainThread"}, {"name": "framework", "value": "pytest"}, {"name": "language", "value": "cpython3"}, {"name": "package", "value": "pytest.api.test_get_intent"}]}